Workbook

Sheet Portfolio Management
B2: Stock Returns | E2: Stock Return Statistics | I2: Portfolio Weighting | O2: Capital Allocation Line
B3: CI | C3: EBAY | F3: CI | G3: EBAY | I3: CI | J3: EBAY | K3: Port Return | L3: Port St Dev | M3: Sharpe Ratio | O3: Weight | P3: Return | Q3: St Dev
B4: 0.066588043 | C4: 0.048221111 | E4: average | F4: =AVERAGE(B4:B62) -> 0.005667299 | G4: =AVERAGE(C4:C62) -> 0.0049795291 | I4: 1 | J4: 0 | K4: =(I4*$F$4)+(J4*$G$4) -> 0.005667299 | L4: =((I4^2*$F$5^2)+(J4^2*$G$5^2)+(2*I4*J4*$F$6))^(1/2) -> 0.079262927 | M4: =(K4-$F$7)/L4 -> 0.042188218 | O4: 0 | P4: =(O4*$K$11)+((1-O4)*$F$7) -> 0.0023233374 | Q4: =(O4*$L$11) -> 0
B5: 0.046878543 | C5: -0.042323139 | E5: St Dev | F5: =_xlfn.STDEV.P(B4:B62) -> 0.079262927 | G5: =_xlfn.STDEV.P(C4:C62) -> 0.090122992 | I5: 0.95 | J5: 0.05 | K5: =(I5*$F$4)+(J5*$G$4) -> 0.0056329105 | L5: =((I5^2*$F$5^2)+(J5^2*$G$5^2)+(2*I5*J5*$F$6))^(1/2) -> 0.076311417 | M5: =(K5-$F$7)/L5 -> 0.043369306 | O5: 1 | P5: =(O5*$K$11)+((1-O5)*$F$7) -> 0.0054265796 | Q5: =(O5*$L$11) -> 0.065472913
B6: 0.056152277 | C6: 0.081950207 | E6: Covariance | F6: =_xlfn.COVARIANCE.P(B4:B62,C4:C62) -> 0.0014007365 | I6: 0.9 | J6: 0.1 | K6: =(I6*$F$4)+(J6*$G$4) -> 0.0055985221 | L6: =((I6^2*$F$5^2)+(J6^2*$G$5^2)+(2*I6*J6*$F$6))^(1/2) -> 0.073636061 | M6: =(K6-$F$7)/L6 -> 0.044477999 | O6: 1.5 | P6: =(O6*$K$11)+((1-O6)*$F$7) -> 0.0069782007 | Q6: =(O6*$L$11) -> 0.09820937
B7: -0.21654422 | C7: -0.025988701 | E7: risk free | F7: ='10YR Treasury'!E69 -> 0.0023233374 | I7: 0.85 | J7: 0.15 | K7: =(I7*$F$4)+(J7*$G$4) -> 0.0055641336 | L7: =((I7^2*$F$5^2)+(J7^2*$G$5^2)+(2*I7*J7*$F$6))^(1/2) -> 0.071267967 | M7: =(K7-$F$7)/L7 -> 0.045473392
B8: 0.068766466 | C8: 0.095185651 | I8: 0.8 | J8: 0.2 | K8: =(I8*$F$4)+(J8*$G$4) -> 0.0055297451 | L8: =((I8^2*$F$5^2)+(J8^2*$G$5^2)+(2*I8*J8*$F$6))^(1/2) -> 0.069238669 | M8: =(K8-$F$7)/L8 -> 0.046309494
B9: -0.10569648 | C9: -0.13215093 | I9: 0.75 | J9: 0.25 | K9: =(I9*$F$4)+(J9*$G$4) -> 0.0054953566 | L9: =((I9^2*$F$5^2)+(J9^2*$G$5^2)+(2*I9*J9*$F$6))^(1/2) -> 0.067578694 | M9: =(K9-$F$7)/L9 -> 0.046938155
B10: -0.039732053 | C10: 0.088158501 | I10: 0.7 | J10: 0.3 | K10: =(I10*$F$4)+(J10*$G$4) -> 0.0054609681 | L10: =((I10^2*$F$5^2)+(J10^2*$G$5^2)+(2*I10*J10*$F$6))^(1/2) -> 0.066315781 | M10: =(K10-$F$7)/L10 -> 0.047313485
B11: 0.0357528 | C11: 0.063331649 | E11: Complete Portfolio | I11: 0.65 | J11: 0.35 | K11: =(I11*$F$4)+(J11*$G$4) -> 0.0054265796 | L11: =((I11^2*$F$5^2)+(J11^2*$G$5^2)+(2*I11*J11*$F$6))^(1/2) -> 0.065472913 | M11: =(K11-$F$7)/L11 -> 0.047397344
B12: 0.049151181 | C12: 0.033986693 | E12: 3 | F12: ='Portfolio Management'!K11 -> 0.0054265796 | I12: 0.6 | J12: 0.4 | K12: =(I12*$F$4)+(J12*$G$4) -> 0.0053921911 | L12: =((I12^2*$F$5^2)+(J12^2*$G$5^2)+(2*I12*J12*$F$6))^(1/2) -> 0.065066414 | M12: =(K12-$F$7)/L12 -> 0.047164943
B13: -0.038301466 | C13: -0.014333582 | E13: St Dev of Optimal Risky Portfolio | F13: ='Portfolio Management'!L11 -> 0.065472913 | I13: 0.55 | J13: 0.45 | K13: =(I13*$F$4)+(J13*$G$4) -> 0.0053578026 | L13: =((I13^2*$F$5^2)+(J13^2*$G$5^2)+(2*I13*J13*$F$6))^(1/2) -> 0.06510446 | M13: =(K13-$F$7)/L13 -> 0.046609176
B14: -0.037469502 | C14: 0.054138374 | E14: Risk-free rate | F14: ='Portfolio Management'!F7 -> 0.0023233374 | I14: 0.5 | J14: 0.5 | K14: =(I14*$F$4)+(J14*$G$4) -> 0.0053234141 | L14: =((I14^2*$F$5^2)+(J14^2*$G$5^2)+(2*I14*J14*$F$6))^(1/2) -> 0.065586276 | M14: =(K14-$F$7)/L14 -> 0.045742447
B15: -0.020745842 | C15: -0.029297633 | E15: Risk Aversion | F15: 3 | I15: 0.45 | J15: 0.55 | K15: =(I15*$F$4)+(J15*$G$4) -> 0.0052890256 | L15: =((I15^2*$F$5^2)+(J15^2*$G$5^2)+(2*I15*J15*$F$6))^(1/2) -> 0.066502217 | M15: =(K15-$F$7)/L15 -> 0.044595329
B16: 0.079184838 | C16: 0.10876532 | E16: Investment | F16: 10000 | I16: 0.4 | J16: 0.6 | K16: =(I16*$F$4)+(J16*$G$4) -> 0.0052546371 | L16: =((I16^2*$F$5^2)+(J16^2*$G$5^2)+(2*I16*J16*$F$6))^(1/2) -> 0.067834701 | M16: =(K16-$F$7)/L16 -> 0.043212392
B17: 0.10318122 | C17: 0.13134518 | I17: 0.35 | J17: 0.65 | K17: =(I17*$F$4)+(J17*$G$4) -> 0.0052202486 | L17: =((I17^2*$F$5^2)+(J17^2*$G$5^2)+(2*I17*J17*$F$6))^(1/2) -> 0.069559794 | M17: =(K17-$F$7)/L17 -> 0.041646346
B18: 0.001129268 | C18: -0.062089116 | I18: 0.3 | J18: 0.7 | K18: =(I18*$F$4)+(J18*$G$4) -> 0.0051858601 | L18: =((I18^2*$F$5^2)+(J18^2*$G$5^2)+(2*I18*J18*$F$6))^(1/2) -> 0.071649143 | M18: =(K18-$F$7)/L18 -> 0.039951947
B19: 0.12582297 | C19: 0.054103622 | I19: 0.25 | J19: 0.75 | K19: =(I19*$F$4)+(J19*$G$4) -> 0.0051514716 | L19: =((I19^2*$F$5^2)+(J19^2*$G$5^2)+(2*I19*J19*$F$6))^(1/2) -> 0.07407193 | M19: =(K19-$F$7)/L19 -> 0.038180917
B20: -0.17569418 | C20: 0.049200194 | E20: Optimal Allocation Computation | F20: =(F12-F14)/(F15*(F13)^2) -> 0.24130765 | I20: 0.2 | J20: 0.8 | K20: =(I20*$F$4)+(J20*$G$4) -> 0.0051170831 | L20: =((I20^2*$F$5^2)+(J20^2*$G$5^2)+(2*I20*J20*$F$6))^(1/2) -> 0.076796605 | M20: =(K20-$F$7)/L20 -> 0.036378506
B21: 0.070464913 | C21: -0.12388478 | E21: Optimal Risky Portfolio Allocation | F21: =F20 -> 0.24130765 | I21: 0.15 | J21: 0.85 | K21: =(I21*$F$4)+(J21*$G$4) -> 0.0050826946 | L21: =((I21^2*$F$5^2)+(J21^2*$G$5^2)+(2*I21*J21*$F$6))^(1/2) -> 0.079792246 | M21: =(K21-$F$7)/L21 -> 0.034581772
B22: 0.038042532 | C22: -0.021320027 | E22: Optimal T-Notes Allocation | F22: =1-F21 -> 0.75869235 | I22: 0.1 | J22: 0.9 | K22: =(I22*$F$4)+(J22*$G$4) -> 0.0050483061 | L22: =((I22^2*$F$5^2)+(J22^2*$G$5^2)+(2*I22*J22*$F$6))^(1/2) -> 0.083029532 | M22: =(K22-$F$7)/L22 -> 0.032819272
B23: -0.067732832 | C23: 0.011547857 | I23: 0.05 | J23: 0.95 | K23: =(I23*$F$4)+(J23*$G$4) -> 0.0050139176 | L23: =((I23^2*$F$5^2)+(J23^2*$G$5^2)+(2*I23*J23*$F$6))^(1/2) -> 0.086481328 | M23: =(K23-$F$7)/L23 -> 0.03111169
B24: 0.045272789 | C24: -0.004044035 | E24: Optimal Risky Portfolio | F24: =F16*F21 -> 2413.0765 | I24: 0 | J24: 1 | K24: =(I24*$F$4)+(J24*$G$4) -> 0.0049795291 | L24: =((I24^2*$F$5^2)+(J24^2*$G$5^2)+(2*I24*J24*$F$6))^(1/2) -> 0.090122992 | M24: =(K24-$F$7)/L24 -> 0.029472965
B25: 0.12153049 | C25: 0.042515104 | E25: T-Notes | F25: =F16*F22 -> 7586.9235
B26: -0.023393939 | C26: -0.085066604
B27: -0.012831142 | C27: 0.038983416 | E27: Optimal Risky Portfolio Weights
B28: -0.13756139 | C28: -0.028686688 | E28: Ebay | F28: ='Portfolio Management'!J11 -> 0.35 | G28: =F24*F28 -> 844.57678
B29: -0.085118048 | C29: -0.078431373 | E29: Cigna | F29: ='Portfolio Management'!I11 -> 0.65 | G29: =F24*F29 -> 1568.4997
B30: -0.049957369 | C30: 0.16222222
B31: 0.0116996 | C31: -0.10103689 | E31: Asset | F31: Allocation | G31: Weight
B32: 0.016281193 | C32: 0.12746386 | E32: T-Notes | F32: =F25 -> 7586.9235 | G32: =F32/$F$35 -> 0.75869235
B33: 0.1374478 | C33: 0.076054217 | E33: Cigna | F33: =G29 -> 1568.4997 | G33: =F33/$F$35 -> 0.15684997
B34: -0.01656983 | C34: -0.20483564 | E34: eBay | F34: =G28 -> 844.57678 | G34: =F34/$F$35 -> 0.084457678
B35: 0.028506915 | C35: -0.096505073 | E35: Total | F35: =SUM(F32:F34) -> 10000 | G35: =SUM(G32:G34) -> 1
B36: 0.038858222 | C36: 0.14312153
B37: -0.014471397 | C37: -0.17326614
B38: 0.080822377 | C38: -0.061975864
B39: 0.024474249 | C39: -0.10708783
B40: 0.012502596 | C40: 0.050278358
B41: 0.031294692 | C41: -0.10038469
...

Sheet Excess Return Analysis
B2: Stock Excess Returns | H2: Correlation
B3: CI | C3: KMB | D3: EBAY | E3: CAT | F3: SPX | I3: CI | J3: KMB | K3: EBAY | L3: CAT | M3: SPX
B4: {='CI - Stock PX'!G8:G66} -> 0.063083627 | C4: {='KMB - Stock PX'!G8:G66} -> 0.0067409137 | D4: {='EBAY - Stock PX'!G8:G66} -> 0.044716695 | E4: {='CAT - Stock PX'!G8:G66} -> -0.046409207 | F4: {='SPX - Tot Ret'!D2:D60} -> -0.061058296 | H4: CI | I4: =CORREL(_xlfn.ANCHORARRAY(B4),_xlfn.ANCHORARRAY(B4)) -> 1 | J4: =CORREL(_xlfn.ANCHORARRAY(B4),_xlfn.ANCHORARRAY(C4)) -> 0.22710209 | K4: =CORREL(_xlfn.ANCHORARRAY(B4),_xlfn.ANCHORARRAY(D4)) -> 0.19707199 | L4: =CORREL(_xlfn.ANCHORARRAY(B4),_xlfn.ANCHORARRAY(E4)) -> 0.38248323 | M4: =CORREL(_xlfn.ANCHORARRAY(B4),_xlfn.ANCHORARRAY(F4)) -> 0.22033806
B5: 0.04337171 | C5: 0.081275928 | D5: -0.045829972 | E5: -0.087530674 | F5: -0.014447897 | H5: KMB | I5: 0.22710209 | J5: 1 | K5: =CORREL(_xlfn.ANCHORARRAY(C4),_xlfn.ANCHORARRAY(D4)) -> 0.33701044 | L5: =CORREL(_xlfn.ANCHORARRAY(C4),_xlfn.ANCHORARRAY(E4)) -> 0.16257082 | M5: =CORREL(_xlfn.ANCHORARRAY(C4),_xlfn.ANCHORARRAY(F4)) -> 0.30229223
B6: 0.052370027 | C6: -0.021401701 | D6: 0.078167957 | E6: 0.023279571 | F6: 0.026305639 | H6: EBAY | I6: 0.19707199 | J6: 0.33701044 | K6: 1 | L6: =CORREL(_xlfn.ANCHORARRAY(D4),_xlfn.ANCHORARRAY(E4)) -> 0.60939707 | M6: =CORREL(_xlfn.ANCHORARRAY(D4),_xlfn.ANCHORARRAY(F4)) -> 0.69529735
B7: -0.22035172 | C7: -0.057414033 | D7: -0.029796201 | E7: -0.123308 | F7: -0.02563065 | H7: CAT | I7: 0.38248323 | J7: 0.16257082 | K7: 0.60939707 | L7: 1 | M7: =CORREL(_xlfn.ANCHORARRAY(E4),_xlfn.ANCHORARRAY(F4)) -> 0.68508414
B8: 0.065292716 | C8: 0.033627075 | D8: 0.091711901 | E8: 0.066704281 | F8: 0.054195856 | H8: SPX | I8: 0.22033806 | J8: 0.30229223 | K8: 0.69529735 | L8: 0.68508414 | M8: 1
B9: -0.10926682 | C9: -0.073029269 | D9: -0.13572126 | E9: -0.039347988 | F9: -0.0099957059
B10: -0.042882803 | C10: -0.011234374 | D10: 0.085007751 | E10: 0.086386988 | F10: 0.019797032 | H10: Covarience
B11: 0.032499966 | C11: 0.063178799 | D11: 0.060078816 | E11: 0.020588784 | F11: 0.022324906 | I11: CI | J11: KMB | K11: EBAY | L11: CAT | M11: SPX
B12: 0.045793181 | C12: -0.035716386 | D12: 0.030628693 | E12: 0.038384182 | F12: 0.011194611 | H12: CI | I12: =VARP('Excess Return Analysis'!$B$4:$B$62) -> 0.0062842314 | J12: 0.00096292944 | K12: 0.0014092895 | L12: 0.0026455691 | M12: 0.00080819174
B13: -0.041964882 | C13: 0.040232724 | D13: -0.017996998 | E13: -0.019934807 | F13: 0.033508043 | H13: KMB | I13: 0.00096292944 | J13: =VARP('Excess Return Analysis'!$C$4:$C$62) -> 0.002860846 | K13: 0.0016260722 | L13: 0.00075870067 | M13: 0.00074812302
B14: -0.041218252 | C14: -0.027979808 | D14: 0.050389624 | E14: 0.0040794433 | F14: 0.045820851 | H14: EBAY | I14: 0.0014092895 | J14: 0.0016260722 | K14: =VARP('Excess Return Analysis'!$D$4:$D$62) -> 0.0081376401 | L14: 0.0047965639 | M14: 0.0029021417
B15: -0.024645676 | C15: 0.039753576 | D15: -0.033197466 | E15: -0.094887418 | F15: -0.043422053 | H15: CAT | I15: 0.0026455691 | J15: 0.00075870067 | K15: 0.0047965639 | L15: =VARP('Excess Return Analysis'!$E$4:$E$62) -> 0.0076130951 | M15: 0.0027658163
B16: 0.075684588 | C16: 0.068491785 | D16: 0.10526507 | E16: 0.08511149 | F16: 0.030085548 | H16: SPX | I16: 0.00080819174 | J16: 0.00074812302 | K16: 0.0029021417 | L16: 0.0027658163 | M16: =VARP('Excess Return Analysis'!$F$4:$F$62) -> 0.0021409059
B17: 0.099639389 | C17: -0.0018912598 | D17: 0.12780334 | E17: 0.093326055 | F17: 0.049177143
B18: -0.0021310654 | C18: -0.017478735 | D18: -0.065349449 | E18: 0.016433974 | F18: 0.015647024
B19: 0.12259039 | C19: -0.011709232 | D19: 0.050871039 | E19: 0.14879502 | F19: 0.042355807 | H19: Stock Beta's | L19: Stock Alpha's
B20: -0.17929951 | C20: 0.029450514 | D20: 0.045594861 | E20: 0.089606217 | F20: 0.08187749 | I20: Via Data | J20: Via Slope | M20: Via Intercept
B21: 0.066355996 | C21: -0.024085513 | D21: -0.1279937 | E21: -0.20490065 | F21: -0.022473652 | H21: CI Beta | I21: =I16/F64 -> 0.37749988 | J21: =SLOPE(_xlfn.ANCHORARRAY(B4),_xlfn.ANCHORARRAY(F4)) -> 0.37749988 | L21: CI Alpha | M21: =INTERCEPT(_xlfn.ANCHORARRAY(B4),_xlfn.ANCHORARRAY(F4)) -> -0.0005103403
B22: 0.034233282 | C22: -0.059533252 | D22: -0.025129277 | E22: -0.03358947 | F22: -0.051214421 | H22: KMB Beta | I22: =J16/F64 -> 0.34944226 | J22: =SLOPE(_xlfn.ANCHORARRAY(C4),_xlfn.ANCHORARRAY(F4)) -> 0.34944226 | L22: KMB Alpha | M22: =INTERCEPT(_xlfn.ANCHORARRAY(C4),_xlfn.ANCHORARRAY(F4)) -> -0.0067336438
B23: -0.071156248 | C23: -0.0055192018 | D23: 0.0081244403 | E23: 0.048723277 | F23: -0.018035965 | H23: EBAY Beta | I23: =K16/F64 -> 1.3555671 | J23: =SLOPE(_xlfn.ANCHORARRAY(D4),_xlfn.ANCHORARRAY(F4)) -> 1.3555671 | L23: EBAY Alpha | M23: =INTERCEPT(_xlfn.ANCHORARRAY(D4),_xlfn.ANCHORARRAY(F4)) -> -0.010968099
B24: 0.041973789 | C24: -0.081842765 | D24: -0.007343035 | E24: 0.073332516 | F24: 0.030198564 | H24: CAT Beta | I24: =L16/F64 -> 1.2918906 | J24: =SLOPE(_xlfn.ANCHORARRAY(E4),_xlfn.ANCHORARRAY(F4)) -> 1.2918906 | L24: CAT Alpha | M24: =INTERCEPT(_xlfn.ANCHORARRAY(E4),_xlfn.ANCHORARRAY(F4)) -> -0.0018089424
B25: 0.11833324 | C25: 0.032424698 | D25: 0.039317854 | E25: 0.1605906 | F25: 0.060792562
B26: -0.026429439 | C26: -0.082049501 | D26: -0.088102104 | E26: -0.072294309 | F26: 0.0024761773
B27: -0.015682809 | C27: 0.062646297 | D27: 0.036131749 | E27: -0.043033485 | F27: 0.014431056
B28: -0.14045106 | C28: 0.073550511 | D28: -0.031576354 | E28: -0.049690925 | F28: 0.033864566
B29: -0.088384715 | C29: -0.042930801 | D29: -0.081698039 | E29: -0.061459111 | F29: -0.026812589
B30: -0.052879786 | C30: -0.055995257 | D30: 0.15929981 | E30: 0.052030441 | F30: 0.058161213
B31: 0.0084706 | C31: 0.0061202075 | D31: -0.10426589 | E31: 0.0099201067 | F31: -0.062667014
B32: 0.013276693 | C32: 0.079351911 | D32: 0.12445936 | E32: 0.076306866 | F32: 0.05101088
B33: 0.13407463 | C33: 0.083080312 | D33: 0.07268105 | E33: 0.24279057 | F33: 0.073956994
B34: -0.01976033 | C34: -0.12473843 | D34: -0.20802614 | E34: -0.12892185 | F34: -0.10301705
B35: 0.025846415 | C35: -0.036145444 | D35: -0.099165573 | E35: -0.082461269 | F35: -0.044321113
B36: 0.036650972 | C36: -0.036504238 | D36: 0.14091428 | E36: 0.10152802 | F36: 0.083507453
... B62: 0.0050376564 | C62: 0.020383768 | D62: 0.12790256 | E62: 0.022098304 | F62: 0.043320161
F63: =_xlfn.STDEV.P(F4:F62) -> 0.046269925 | G63: SD
F64: =F63*F63 -> 0.0021409059 | G64: Variance

Sheet DDM
B3: BASE CASE | H3: BULL CASE | N3: BEAR CASE
B4: Assumptions | H4: Assumptions | N4: Assumptions
B5: Rate of Return | C5: ='CAPM and WACC'!B5 -> 0.082102733 | H5: Rate of Return | I5: ='CAPM and WACC'!B5 -> 0.082102733 | N5: Rate of Return | O5: ='CAPM and WACC'!B5 -> 0.082102733
B6: Short term growth | C6: 0.14 | H6: Short term growth | I6: 0.16 | N6: Short term growth | O6: 0.12
B7: Mid term growth | C7: 0.08 | H7: Mid term growth | I7: 0.1 | N7: Mid term growth | O7: 0.07
B8: Long term growth | C8: 0.03 | H8: Long term growth | I8: 0.03 | N8: Long term growth | O8: 0.03
B11: Years(index) | C11: Years | D11: DPS | E11: Growth Rate | F11: Discounted | H11: Years(index) | I11: Years | J11: DPS | K11: Growth Rate | L11: Discounted | N11: Years(index) | O11: Years | P11: DPS | Q11: Growth Rate | R11: Discounted
B12: -4 | C12: 2020 | D12: 0.64 | H12: -4 | I12: 2020 | J12: 0.64 | N12: -4 | O12: 2020 | P12: 0.64
B13: -3 | C13: 2021 | D13: 0.72 | E13: =(D13-D12)/D12 -> 0.125 | H13: -3 | I13: 2021 | J13: 0.72 | K13: =(J13-J12)/J12 -> 0.125 | N13: -3 | O13: 2021 | P13: 0.72 | Q13: =(P13-P12)/P12 -> 0.125
B14: -2 | C14: 2022 | D14: 0.88 | E14: =(D14-D13)/D13 -> 0.22222222 | H14: -2 | I14: 2022 | J14: 0.88 | K14: =(J14-J13)/J13 -> 0.22222222 | N14: -2 | O14: 2022 | P14: 0.88 | Q14: =(P14-P13)/P13 -> 0.22222222
B15: -1 | C15: 2023 | D15: 1 | E15: =(D15-D14)/D14 -> 0.13636364 | H15: -1 | I15: 2023 | J15: 1 | K15: =(J15-J14)/J14 -> 0.13636364 | N15: -1 | O15: 2023 | P15: 1 | Q15: =(P15-P14)/P14 -> 0.13636364
B16: 0 | C16: 2024 | D16: 1.08 | E16: =(D16-D15)/D15 -> 0.08 | H16: 0 | I16: 2024 | J16: 1.08 | K16: =(J16-J15)/J15 -> 0.08 | N16: 0 | O16: 2024 | P16: 1.08 | Q16: =(P16-P15)/P15 -> 0.08
B17: 1 | C17: 2025 | D17: =D16*(1+E17) -> 1.2321682 | E17: =AVERAGE($E$12:$E$16) -> 0.14089646 | F17: =D17/((1+$C$5)^B17) -> 1.1386795 | H17: 1 | I17: 2025 | J17: =J16*(1+K17) -> 1.2528 | K17: =$I$6 -> 0.16 | L17: =J17/((1+$C$5)^H17) -> 1.1577459 | N17: 1 | O17: 2025 | P17: =P16*(1+Q17) -> 1.2096 | Q17: 0.12 | R17: =P17/((1+$C$5)^N17) -> 1.1178236
B18: 2 | C18: 2026 | D18: =D17*(1+E18) -> 1.4057763 | E18: =AVERAGE($E$12:$E$16) -> 0.14089646 | F18: =D18/((1+$C$5)^B18) -> 1.2005472 | H18: 2 | I18: 2026 | J18: =J17*(1+K18) -> 1.453248 | K18: =$I$6 -> 0.16 | L18: =J18/((1+$C$5)^H18) -> 1.2410885 | N18: 2 | O18: 2026 | P18: =P17*(1+Q18) -> 1.354752 | Q18: 0.12 | R18: =P18/((1+$C$5)^N18) -> 1.1569719
B19: 3 | C19: 2027 | D19: =D18*(1+E19) -> 1.6038452 | E19: =AVERAGE($E$12:$E$16) -> 0.14089646 | F19: =D19/((1+$C$5)^B19) -> 1.2657764 | H19: 3 | I19: 2027 | J19: =J18*(1+K19) -> 1.6857677 | K19: =$I$6 -> 0.16 | L19: =J19/((1+$C$5)^H19) -> 1.3304307 | N19: 3 | O19: 2027 | P19: =P18*(1+Q19) -> 1.5173222 | Q19: 0.12 | R19: =P19/((1+$C$5)^N19) -> 1.1974912
B20: 4 | C20: 2028 | D20: =D19*(1+E20) -> 1.8298214 | E20: =AVERAGE($E$12:$E$16) -> 0.14089646 | F20: =D20/((1+$C$5)^B20) -> 1.3345496 | H20: 4 | I20: 2028 | J20: =J19*(1+K20) -> 1.9554905 | K20: =$I$6 -> 0.16 | L20: =J20/((1+$C$5)^H20) -> 1.4262043 | N20: 4 | O20: 2028 | P20: =P19*(1+Q20) -> 1.6994009 | Q20: 0.12 | R20: =P20/((1+$C$5)^N20) -> 1.2394296
B21: 5 | C21: 2029 | D21: =D20*(1+E21) -> 2.0859964 | E21: 0.14 | F21: =D21/((1+$C$5)^B21) -> 1.4059539 | H21: 5 | I21: 2029 | J21: =J20*(1+K21) -> 2.268369 | K21: =$I$6 -> 0.16 | L21: =J21/((1+$C$5)^H21) -> 1.5288724 | N21: 5 | O21: 2029 | P21: =P20*(1+Q21) -> 1.818359 | Q21: 0.07 | R21: =P21/((1+$C$5)^N21) -> 1.2255673
B22: 6 | C22: 2030 | D22: =D21*(1+E22) -> 2.3780358 | E22: 0.14 | F22: =D22/((1+$C$5)^B22) -> 1.4811786 | H22: 6 | I22: 2030 | J22: =J21*(1+K22) -> 2.631308 | K22: =$I$6 -> 0.16 | L22: =J22/((1+$C$5)^H22) -> 1.6389312 | N22: 6 | O22: 2030 | P22: =P21*(1+Q22) -> 1.9456441 | Q22: 0.07 | R22: =P22/((1+$C$5)^N22) -> 1.21186
B23: 7 | C23: 2031 | D23: =D22*(1+E23) -> 2.5682787 | E23: =0.08 -> 0.08 | F23: =D23/((1+$C$5)^B23) -> 1.4783004 | H23: 7 | I23: 2031 | J23: =J22*(1+K23) -> 2.8944388 | K23: 0.1 | L23: =J23/((1+$C$5)^H23) -> 1.6660381 | N23: 7 | O23: 2031 | P23: =P22*(1+Q23) -> 2.0818392 | Q23: 0.07 | R23: =P23/((1+$C$5)^N23) -> 1.198306
B24: 8 | C24: 2032 | D24: =D23*(1+E24) -> 2.773741 | E24: 0.08 | F24: =D24/((1+$C$5)^B24) -> 1.4754278 | H24: 8 | I24: 2032 | J24: =J23*(1+K24) -> 3.1838827 | K24: 0.1 | L24: =J24/((1+$C$5)^H24) -> 1.6935932 | N24: 8 | O24: 2032 | P24: =P23*(1+Q24) -> 2.2275679 | Q24: 0.07 | R24: =P24/((1+$C$5)^N24) -> 1.1849036
B25: 9 | C25: 2033 | D25: =D24*(1+E25) -> 2.9956403 | E25: 0.08 | F25: =D25/((1+$C$5)^B25) -> 1.4725607 | H25: 9 | I25: 2033 | J25: =J24*(1+K25) -> 3.502271 | K25: 0.1 | L25: =J25/((1+$C$5)^H25) -> 1.7216042 | N25: 9 | O25: 2033 | P25: =P24*(1+Q25) -> 2.294395 | Q25: 0.03 | R25: =P25/((1+$C$5)^N25) -> 1.127851
B26: 10 | C26: 2034 | D26: =D25*(1+E26) -> 3.0855095 | E26: 0.03 | F26: =D26/((1+$C$5)^B26) -> 1.4016576 | H26: 10 | I26: 2034 | J26: =J25*(1+K26) -> 3.6073391 | K26: 0.03 | L26: =J26/((1+$C$5)^H26) -> 1.6387097 | N26: 10 | O26: 2034 | P26: =P25*(1+Q26) -> 2.3632268 | Q26: 0.03 | R26: =P26/((1+$C$5)^N26) -> 1.0735455
B29: PV opf 10y Dividends | C29: =SUM(F17:F26) -> 13.654632 | H29: PV opf 10y Dividends | I29: =SUM(L17:L26) -> 15.043218 | N29: PV opf 10y Dividends | O29: =SUM(R17:R26) -> 11.73375
B30: PV of Terminal Value | C30: =-PV(C5,10,0,(D26*(1+C8)/(C5-C8))) -> 27.708861 | H30: PV of Terminal Value | I30: =-PV(I5,10,0,(J26*(1+I8)/(I5-I8))) -> 32.395058 | N30: PV of Terminal Value | O30: =-PV(O5,10,0,(P26*(1+O8)/(O5-O8))) -> 21.222532
B31: Sum of Total | C31: =SUM(C29:C30) -> 41.363493 | H31: Sum of Total | I31: =SUM(I29:I30) -> 47.438276 | N31: Sum of Total | O31: =SUM(O29:O30) -> 32.956282
B33: Current Market Value | C33: 67.05 | H33: Current Market Value | I33: 67.05 | N33: Current Market Value | O33: 67.05
B34: Valuation Gap | C34: =(C31-C33)/C33 -> -0.38309481 | D34: SELL | H34: Valuation Gap | I34: =(I31-I33)/I33 -> -0.29249402 | J34: SELL | N34: Valuation Gap | O34: =(O31-O33)/O33 -> -0.50848201 | P34: SELL

Sheet FCFF
B2: BASE CASE | I2: BULL CASE | P2: BEAR CASE
B3: Assumptions: | I3: Assumptions: | P3: Assumptions:
B4: Tax Rate | C4: =-AVERAGE('EBAY Income Statement'!$B$25:$G$25) -> 0.22365735 | D4: Source: FactSet | I4: Tax Rate | J4: =-AVERAGE('EBAY Income Statement'!$B$25:$G$25) -> 0.22365735 | K4: Source: FactSet | P4: Tax Rate | Q4: =-AVERAGE('EBAY Income Statement'!$B$25:$G$25) -> 0.22365735 | R4: Source: FactSet
B5: Revenue growth | C5: 0.075 | D5: Source: Value Line | I5: Revenue growth | J5: 0.085 | K5: Source: Value Line | P5: Revenue growth | Q5: 0.065 | R5: Source: Value Line
B6: COGS as % Rev | C6: =(AVERAGE('EBAY Income Statement'!$B$6:$G$6)/AVERAGE('EBAY Income Statement'!$B$5:$G$5)) -> -0.25336799 | I6: COGS as % Rev | J6: -0.23 | P6: COGS as % Rev | Q6: =-0.27 -> -0.27
B7: Expenses as % of Rev | C7: =AVERAGE('EBAY Income Statement'!$B$8:$G$8)/AVERAGE('EBAY Income Statement'!$B$5:$G$5) -> -0.50181793 | I7: Expenses as % of Rev | J7: -0.47 | P7: Expenses as % of Rev | Q7: -0.52
B8: Dep & Amort | C8: =-'EBAY Income Statement'!$H$14 -> 0.0020164269 | I8: Dep & Amort | J8: =-'EBAY Income Statement'!$H$14 -> 0.0020164269 | P8: Dep & Amort | Q8: =-'EBAY Income Statement'!$H$14 -> 0.0020164269
B9: CAPEX as % of Rev | C9: ='EBAY Balance Sheet'!$H$21 -> 0.13875833 | I9: CAPEX as % of Rev | J9: ='EBAY Balance Sheet'!$H$21 -> 0.13875833 | P9: CAPEX as % of Rev | Q9: ='EBAY Balance Sheet'!$H$21 -> 0.13875833
B10: Required rate of return | C10: ='CAPM and WACC'!$B$7 -> 0.0769 | D10: Source: FactSet | I10: Required rate of return | J10: ='CAPM and WACC'!$B$7 -> 0.0769 | K10: Source: FactSet | P10: Required rate of return | Q10: ='CAPM and WACC'!$B$7 -> 0.0769 | R10: Source: FactSet
B11: Terminal Growth Rate | C11: 0.025 | I11: Terminal Growth Rate | J11: 0.027 | P11: Terminal Growth Rate | Q11: 0.023
B13: Year (index) | C13: 1 | D13: 1 | E13: 3 | F13: 4 | G13: 5 | I13: Year (index) | J13: 1 | K13: 1 | L13: 3 | M13: 4 | N13: 5 | P13: Year (index) | Q13: 1 | R13: 1 | S13: 3 | T13: 4 | U13: 5
B14: Year | C14: 2025 | D14: 2026 | E14: 2027 | F14: 2028 | G14: 2029 | I14: Year | J14: 2025 | K14: 2026 | L14: 2027 | M14: 2028 | N14: 2029 | P14: Year | Q14: 2025 | R14: 2026 | S14: 2027 | T14: 2028 | U14: 2029
B15: Sales | C15: ='EBAY Income Statement'!$G$5*(1+$C$5) -> 11054.225 | D15: =C15*(1+$C$5) -> 11883.292 | E15: =D15*(1+$C$5) -> 12774.539 | F15: =E15*(1+$C$5) -> 13732.629 | G15: =F15*(1+$C$5) -> 14762.576 | I15: Sales | J15: ='EBAY Income Statement'!$G$5*(1+$J$5) -> 11157.055 | K15: =J15*(1+$J$5) -> 12105.405 | L15: =K15*(1+$J$5) -> 13134.364 | M15: =L15*(1+$J$5) -> 14250.785 | N15: =M15*(1+$J$5) -> 15462.102 | P15: Sales | Q15: ='EBAY Income Statement'!$G$5*(1+$Q$5) -> 10951.395 | R15: =Q15*(1+$Q$5) -> 11663.236 | S15: =R15*(1+$Q$5) -> 12421.346 | T15: =S15*(1+$Q$5) -> 13228.733 | U15: =T15*(1+$Q$5) -> 14088.601
B16: COGS | C16: =C15*$C$6 -> -2800.7868 | D16: =D15*$C$6 -> -3010.8458 | E16: =E15*$C$6 -> -3236.6593 | F16: =F15*$C$6 -> -3479.4087 | G16: =G15*$C$6 -> -3740.3644 | I16: COGS | J16: =J15*$J$6 -> -2566.1227 | K16: =K15*$J$6 -> -2784.2431 | L16: =L15*$J$6 -> -3020.9037 | M16: =M15*$J$6 -> -3277.6806 | N16: =N15*$J$6 -> -3556.2834 | P16: COGS | Q16: =Q15*$Q$6 -> -2956.8766 | R16: =R15*$Q$6 -> -3149.0736 | S16: =S15*$Q$6 -> -3353.7634 | T16: =T15*$Q$6 -> -3571.758 | U16: =U15*$Q$6 -> -3803.9223
B17: Gross Profit | C17: =SUM(C15:C16) -> 8253.4382 | D17: =SUM(D15:D16) -> 8872.4461 | E17: =SUM(E15:E16) -> 9537.8795 | F17: =SUM(F15:F16) -> 10253.22 | G17: =SUM(G15:G16) -> 11022.212 | I17: Gross Profit | J17: =SUM(J15:J16) -> 8590.9323 | K17: =SUM(K15:K16) -> 9321.1616 | L17: =SUM(L15:L16) -> 10113.46 | M17: =SUM(M15:M16) -> 10973.104 | N17: =SUM(N15:N16) -> 11905.818 | P17: Gross Profit | Q17: =SUM(Q15:Q16) -> 7994.5183 | R17: =SUM(R15:R16) -> 8514.162 | S17: =SUM(S15:S16) -> 9067.5826 | T17: =SUM(T15:T16) -> 9656.9754 | U17: =SUM(U15:U16) -> 10284.679
B18: Expenses | C18: =C15*$C$7 -> -5547.2083 | D18: =D15*$C$7 -> -5963.2489 | E18: =E15*$C$7 -> -6410.4926 | F18: =F15*$C$7 -> -6891.2795 | G18: =G15*$C$7 -> -7408.1255 | I18: Expenses | J18: =J15*$J$7 -> -5243.8158 | K18: =K15*$J$7 -> -5689.5402 | L18: =L15*$J$7 -> -6173.1511 | M18: =M15*$J$7 -> -6697.869 | N18: =N15*$J$7 -> -7267.1878 | P18: Expenses | Q18: =Q15*$Q$7 -> -5694.7254 | R18: =R15*$Q$7 -> -6064.8826 | S18: =S15*$Q$7 -> -6459.0999 | T18: =T15*$Q$7 -> -6878.9414 | U18: =U15*$Q$7 -> -7326.0726
B19: EBIT | C19: =SUM(C17:C18) -> 2706.2299 | D19: =SUM(D17:D18) -> 2909.1972 | E19: =SUM(E17:E18) -> 3127.387 | F19: =SUM(F17:F18) -> 3361.941 | G19: =SUM(G17:G18) -> 3614.0865 | I19: EBIT | J19: =SUM(J17:J18) -> 3347.1165 | K19: =SUM(K17:K18) -> 3631.6214 | L19: =SUM(L17:L18) -> 3940.3092 | M19: =SUM(M17:M18) -> 4275.2355 | N19: =SUM(N17:N18) -> 4638.6305 | P19: EBIT | Q19: =SUM(Q17:Q18) -> 2299.7929 | R19: =SUM(R17:R18) -> 2449.2795 | S19: =SUM(S17:S18) -> 2608.4827 | T19: =SUM(T17:T18) -> 2778.034 | U19: =SUM(U17:U18) -> 2958.6062
B20: Tax Expense | C20: =-C19*$C$4 -> -605.26822 | D20: =-D19*$C$4 -> -650.66333 | E20: =-E19*$C$4 -> -699.46308 | F20: =-F19*$C$4 -> -751.92281 | G20: =-G19*$C$4 -> -808.31702 | I20: Tax Expense | J20: =-J19*$C$4 -> -748.60721 | K20: =-K19*$C$4 -> -812.23882 | L20: =-L19*$C$4 -> -881.27912 | M20: =-M19*$C$4 -> -956.18785 | N20: =-N19*$C$4 -> -1037.4638 | P20: Tax Expense | Q20: =-Q19*$C$4 -> -514.3656 | R20: =-R19*$C$4 -> -547.79936 | S20: =-S19*$C$4 -> -583.40632 | T20: =-T19*$C$4 -> -621.32773 | U20: =-U19*$C$4 -> -661.71404
B21: NOPAT | C21: =SUM(C19:C20) -> 2100.9617 | D21: =SUM(D19:D20) -> 2258.5338 | E21: =SUM(E19:E20) -> 2427.9239 | F21: =SUM(F19:F20) -> 2610.0182 | G21: =SUM(G19:G20) -> 2805.7695 | I21: NOPAT | J21: =SUM(J19:J20) -> 2598.5093 | K21: =SUM(K19:K20) -> 2819.3826 | L21: =SUM(L19:L20) -> 3059.0301 | M21: =SUM(M19:M20) -> 3319.0477 | N21: =SUM(N19:N20) -> 3601.1667 | P21: NOPAT | Q21: =SUM(Q19:Q20) -> 1785.4274 | R21: =SUM(R19:R20) -> 1901.4801 | S21: =SUM(S19:S20) -> 2025.0763 | T21: =SUM(T19:T20) -> 2156.7063 | U21: =SUM(U19:U20) -> 2296.8922
B22: Dep and Amort | C22: =$C$8*C15 -> 22.290036 | D22: =$C$8*D15 -> 23.961789 | E22: =$C$8*E15 -> 25.758923 | F22: =$C$8*F15 -> 27.690842 | G22: =$C$8*G15 -> 29.767656 | I22: Dep and Amort | J22: =$J$8*J15 -> 22.497385 | K22: =$J$8*K15 -> 24.409663 | L22: =$J$8*L15 -> 26.484485 | M22: =$J$8*M15 -> 28.735666 | N22: =$J$8*N15 -> 31.178197 | P22: Dep and Amort | Q22: =$Q$8*Q15 -> 22.082687 | R22: =$Q$8*R15 -> 23.518062 | S22: =$Q$8*S15 -> 25.046736 | T22: =$Q$8*T15 -> 26.674774 | U22: =$Q$8*U15 -> 28.408634
B23: Change in NWC | C23: -301.37 | D23: {=-'EBAY Balance Sheet'!$R$5:$U$5} -> -346.03867 | E23: -371.99157 | F23: -399.89094 | G23: -429.88276 | I23: Change in NWC | J23: -301.37 | K23: {=-'EBAY Balance Sheet'!$R$5:$U$5} -> -346.03867 | L23: -371.99157 | M23: -399.89094 | N23: -429.88276 | P23: Change in NWC | Q23: -301.37 | R23: {=-'EBAY Balance Sheet'!$R$5:$U$5} -> -346.03867 | S23: -371.99157 | T23: -399.89094 | U23: -429.88276
B24: Captial Expendatures | C24: {=-'EBAY Balance Sheet'!$H$20:$L$20} -> -270.86582 | D24: -115.03994 | E24: -123.66793 | F24: -132.94303 | G24: -142.91375 | I24: Captial Expendatures | J24: {=-'EBAY Balance Sheet'!$H$23:$L$23} -> -285.13434 | K24: -131.59142 | L24: -142.77669 | M24: -154.91271 | N24: -168.08029 | P24: Captial Expendatures | Q24: {=-'EBAY Balance Sheet'!$H$26:$L$26} -> -256.5973 | R24: -98.773825 | S24: -105.19412 | T24: -112.03174 | U24: -119.3138
B25: FCFF | C25: =SUM(C21:C24) -> 1551.0159 | D25: =SUM(D21:D24) -> 1821.417 | E25: =SUM(E21:E24) -> 1958.0233 | F25: =SUM(F21:F24) -> 2104.875 | G25: =SUM(G21:G24) -> 2262.7407 | I25: FCFF | J25: =SUM(J21:J24) -> 2034.5023 | K25: =SUM(K21:K24) -> 2366.1621 | L25: =SUM(L21:L24) -> 2570.7463 | M25: =SUM(M21:M24) -> 2792.9797 | N25: =SUM(N21:N24) -> 3034.3819 | P25: FCFF | Q25: =SUM(Q21:Q24) -> 1249.5427 | R25: =SUM(R21:R24) -> 1480.1857 | S25: =SUM(S21:S24) -> 1572.9374 | T25: =SUM(T21:T24) -> 1671.4584 | U25: =SUM(U21:U24) -> 1776.1043
B26: Present Value | C26: =C25/(1+$C$10)^C13 -> 1440.2599 | D26: =D25/(1+$C$10)^D13 -> 1691.352 | E26: =E25/(1+$C$10)^E13 -> 1567.8038 | F26: =F25/(1+$C$10)^F13 -> 1565.0377 | G26: =G25/(1+$C$10)^G13 -> 1562.2765 | I26: Present Value | J26: =J25/(1+$C$10)^J13 -> 1889.2212 | K26: =K25/(1+$C$10)^K13 -> 2197.1977 | L26: =L25/(1+$C$10)^L13 -> 2058.4157 | M26: =M25/(1+$C$10)^M13 -> 2076.6642 | N26: =N25/(1+$C$10)^N13 -> 2095.045 | P26: Present Value | Q26: =Q25/(1+$C$10)^Q13 -> 1160.3145 | R26: =R25/(1+$C$10)^R13 -> 1374.4876 | S26: =S25/(1+$C$10)^S13 -> 1259.4627 | T26: =T25/(1+$C$10)^T13 -> 1242.7794 | U26: =U25/(1+$C$10)^U13 -> 1226.2854
B28: Sum of PV of FCFF | C28: =SUM(C26:G26) -> 7826.73 | I28: Sum of PV of FCFF | J28: =SUM(J26:N26) -> 10316.544 | P28: Sum of PV of FCFF | Q28: =SUM(Q26:U26) -> 6263.3297
B29: PV of terminal Value | C29: =-PV(C10,5,0,(G25*(1+C11))/(C10-C11)) -> 30854.208 | I29: PV of terminal Value | J29: =-PV(J10,5,0,(N25*(1+J11))/(J10-J11)) -> 43118.46 | P29: PV of terminal Value | Q29: =-PV(Q10,5,0,(U25*(1+Q11))/(Q10-Q11)) -> 23274.397
B30: Enterprise Value | C30: =SUM(C28:C29) -> 38680.938 | I30: Enterprise Value | J30: =SUM(J28:J29) -> 53435.004 | P30: Enterprise Value | Q30: =SUM(Q28:Q29) -> 29537.727
B32: + Cash | C32: ='EBAY Balance Sheet'!$G$9 -> 2433 | I32: + Cash | J32: ='EBAY Balance Sheet'!$G$9 -> 2433 | P32: + Cash | Q32: ='EBAY Balance Sheet'!$G$9 -> 2433
B33: - Debt | C33: =-('EBAY Balance Sheet'!$G$43+'EBAY Balance Sheet'!$G$56) -> -7425 | I33: - Debt | J33: =-('EBAY Balance Sheet'!$G$43+'EBAY Balance Sheet'!$G$56) -> -7425 | P33: - Debt | Q33: =-('EBAY Balance Sheet'!$G$43+'EBAY Balance Sheet'!$G$56) -> -7425
B34: Implied Equity Value | C34: =SUM(C30:C33) -> 33688.938 | I34: Implied Equity Value | J34: =SUM(J30:J33) -> 48443.004 | P34: Implied Equity Value | Q34: =SUM(Q30:Q33) -> 24545.727
B36: Shares outstanding | C36: 479 | I36: Shares outstanding | J36: 479 | P36: Shares outstanding | Q36: 479
B37: Equity Per Share | C37: =C34/C36 -> 70.331812 | I37: Equity Per Share | J37: =J34/J36 -> 101.13362 | P37: Equity Per Share | Q37: =Q34/Q36 -> 51.243689
B39: Current Market Value | C39: 67.05 | I39: Current Market Value | J39: 67.05 | P39: Current Market Value | Q39: 67.05
B40: Valuation Gap | C40: =(C37-C39)/C39 -> 0.048945746 | D40: BUY | I40: Valuation Gap | J40: =(J37-J39)/J39 -> 0.5083314 | K40: BUY | P40: Valuation Gap | Q40: =(Q37-Q39)/Q39 -> -0.23573917 | R40: SELL

Sheet FCFE
B2: BASE CASE | I2: BULL CASE | P2: BEAR CASE
B3: Assumptions: | I3: Assumptions: | P3: Assumptions:
B4: Tax Rate | C4: =-AVERAGE('EBAY Income Statement'!$B$25:$G$25) -> 0.22365735 | D4: Source: FactSet | I4: Tax Rate | J4: =-AVERAGE('EBAY Income Statement'!$B$25:$G$25) -> 0.22365735 | K4: Source: FactSet | P4: Tax Rate | Q4: =-AVERAGE('EBAY Income Statement'!$B$25:$G$25) -> 0.22365735 | R4: Source: FactSet
B5: Revenue growth | C5: 0.075 | D5: Source: Value Line | I5: Revenue growth | J5: 0.085 | K5: Source: Value Line | P5: Revenue growth | Q5: 0.065 | R5: Source: Value Line
B6: COGS as % sales | C6: =(AVERAGE('EBAY Income Statement'!$B$6:$G$6)/AVERAGE('EBAY Income Statement'!$B$5:$G$5)) -> -0.25336799 | I6: COGS as % sales | J6: -0.22 | P6: COGS as % sales | Q6: -0.27
B7: Expenses as % of sales | C7: =(AVERAGE('EBAY Income Statement'!$B$8:$G$8)/AVERAGE('EBAY Income Statement'!$B$5:$G$5)) -> -0.50181793 | I7: Expenses as % of sales | J7: -0.47 | P7: Expenses as % of sales | Q7: -0.52
B8: Interest Expense as % | C8: ='EBAY Income Statement'!$H$19 -> -0.01708644 | I8: Interest Expense as % | J8: ='EBAY Income Statement'!$H$19 -> -0.01708644 | P8: Interest Expense as % | Q8: ='EBAY Income Statement'!$H$19 -> -0.01708644
B9: Dep & Amort | C9: =-'EBAY Income Statement'!$H$14 -> 0.0020164269 | I9: Dep & Amort | J9: =-'EBAY Income Statement'!$H$14 -> 0.0020164269 | P9: Dep & Amort | Q9: =-'EBAY Income Statement'!$H$14 -> 0.0020164269
B10: CAPEX as % of Rev | C10: ='EBAY Balance Sheet'!$H$21 -> 0.13875833 | I10: CAPEX as % of Rev | J10: ='EBAY Balance Sheet'!$H$21 -> 0.13875833 | P10: CAPEX as % of Rev | Q10: ='EBAY Balance Sheet'!$H$21 -> 0.13875833
B11: Debt Issuance % | C11: ='EBAY Cash Flows'!$H$56 -> 0.092158747 | I11: Debt Issuance % | J11: 0.11 | P11: Debt Issuance % | Q11: ='EBAY Cash Flows'!$H$56 -> 0.092158747
B12: Debt Repayment % | C12: ='EBAY Cash Flows'!$H$58 -> -0.14061723 | I12: Debt Repayment % | J12: ='EBAY Cash Flows'!$H$58 -> -0.14061723 | P12: Debt Repayment % | Q12: -0.16
B13: Required Rate of Return | C13: ='CAPM and WACC'!$B$5 -> 0.082102733 | I13: Required Rate of Return | J13: ='CAPM and WACC'!$B$5 -> 0.082102733 | P13: Required Rate of Return | Q13: ='CAPM and WACC'!$B$5 -> 0.082102733
B14: Terminal Growth Rate | C14: 0.025 | I14: Terminal Growth Rate | J14: 0.027 | P14: Terminal Growth Rate | Q14: 0.023
B16: Year (index) | C16: 1 | D16: 2 | E16: 3 | F16: 4 | G16: 5 | I16: Year (index) | J16: 1 | K16: 2 | L16: 3 | M16: 4 | N16: 5 | P16: Year (index) | Q16: 1 | R16: 2 | S16: 3 | T16: 4 | U16: 5
B17: Year | C17: 2025 | D17: 2026 | E17: 2027 | F17: 2028 | G17: 2029 | I17: Year | J17: 2025 | K17: 2026 | L17: 2027 | M17: 2028 | N17: 2029 | P17: Year | Q17: 2025 | R17: 2026 | S17: 2027 | T17: 2028 | U17: 2029
B18: Revenue | C18: ='EBAY Income Statement'!$G$5*(1+$C$5) -> 11054.225 | D18: =C18*(1+$C$5) -> 11883.292 | E18: =D18*(1+$C$5) -> 12774.539 | F18: =E18*(1+$C$5) -> 13732.629 | G18: =F18*(1+$C$5) -> 14762.576 | I18: Revenue | J18: ='EBAY Income Statement'!$G$5*(1+$J$5) -> 11157.055 | K18: =J18*(1+$J$5) -> 12105.405 | L18: =K18*(1+$J$5) -> 13134.364 | M18: =L18*(1+$J$5) -> 14250.785 | N18: =M18*(1+$J$5) -> 15462.102 | P18: Revenue | Q18: ='EBAY Income Statement'!$G$5*(1+$Q$5) -> 10951.395 | R18: =Q18*(1+$Q$5) -> 11663.236 | S18: =R18*(1+$Q$5) -> 12421.346 | T18: =S18*(1+$Q$5) -> 13228.733 | U18: =T18*(1+$Q$5) -> 14088.601
B19: Cogs | C19: =C18*$C$6 -> -2800.7868 | D19: =D18*$C$6 -> -3010.8458 | E19: =E18*$C$6 -> -3236.6593 | F19: =F18*$C$6 -> -3479.4087 | G19: =G18*$C$6 -> -3740.3644 | I19: Cogs | J19: =J18*$J$6 -> -2454.5521 | K19: =K18*$J$6 -> -2663.189 | L19: =L18*$J$6 -> -2889.5601 | M19: =M18*$J$6 -> -3135.1727 | N19: =N18*$J$6 -> -3401.6624 | P19: Cogs | Q19: =Q18*$Q$6 -> -2956.8766 | R19: =R18*$Q$6 -> -3149.0736 | S19: =S18*$Q$6 -> -3353.7634 | T19: =T18*$Q$6 -> -3571.758 | U19: =U18*$Q$6 -> -3803.9223
B20: Gross Profit | C20: =SUM(C18:C19) -> 8253.4382 | D20: =SUM(D18:D19) -> 8872.4461 | E20: =SUM(E18:E19) -> 9537.8795 | F20: =SUM(F18:F19) -> 10253.22 | G20: =SUM(G18:G19) -> 11022.212 | I20: Gross Profit | J20: =SUM(J18:J19) -> 8702.5029 | K20: =SUM(K18:K19) -> 9442.2156 | L20: =SUM(L18:L19) -> 10244.804 | M20: =SUM(M18:M19) -> 11115.612 | N20: =SUM(N18:N19) -> 12060.439 | P20: Gross Profit | Q20: =SUM(Q18:Q19) -> 7994.5183 | R20: =SUM(R18:R19) -> 8514.162 | S20: =SUM(S18:S19) -> 9067.5826 | T20: =SUM(T18:T19) -> 9656.9754 | U20: =SUM(U18:U19) -> 10284.679
B21: Expenses | C21: =C18*$C$7 -> -5547.2083 | D21: =D18*$C$7 -> -5963.2489 | E21: =E18*$C$7 -> -6410.4926 | F21: =F18*$C$7 -> -6891.2795 | G21: =G18*$C$7 -> -7408.1255 | I21: Expenses | J21: =J18*$J$7 -> -5243.8158 | K21: =K18*$J$7 -> -5689.5402 | L21: =L18*$J$7 -> -6173.1511 | M21: =M18*$J$7 -> -6697.869 | N21: =N18*$J$7 -> -7267.1878 | P21: Expenses | Q21: =Q18*$Q$7 -> -5694.7254 | R21: =R18*$Q$7 -> -6064.8826 | S21: =S18*$Q$7 -> -6459.0999 | T21: =T18*$Q$7 -> -6878.9414 | U21: =U18*$Q$7 -> -7326.0726
B22: EBIT | C22: =SUM(C20:C21) -> 2706.2299 | D22: =SUM(D20:D21) -> 2909.1972 | E22: =SUM(E20:E21) -> 3127.387 | F22: =SUM(F20:F21) -> 3361.941 | G22: =SUM(G20:G21) -> 3614.0865 | I22: EBIT | J22: =SUM(J20:J21) -> 3458.687 | K22: =SUM(K20:K21) -> 3752.6754 | L22: =SUM(L20:L21) -> 4071.6529 | M22: =SUM(M20:M21) -> 4417.7434 | N22: =SUM(N20:N21) -> 4793.2515 | P22: EBIT | Q22: =SUM(Q20:Q21) -> 2299.7929 | R22: =SUM(R20:R21) -> 2449.2795 | S22: =SUM(S20:S21) -> 2608.4827 | T22: =SUM(T20:T21) -> 2778.034 | U22: =SUM(U20:U21) -> 2958.6062
B23: Tax Expense | C23: =-C22*($C$4) -> -605.26822 | D23: =-D22*($C$4) -> -650.66333 | E23: =-E22*($C$4) -> -699.46308 | F23: =-F22*($C$4) -> -751.92281 | G23: =-G22*($C$4) -> -808.31702 | I23: Tax Expense | J23: =-J22*($C$4) -> -773.56078 | K23: =-K22*($C$4) -> -839.31345 | L23: =-L22*($C$4) -> -910.65509 | M23: =-M22*($C$4) -> -988.06078 | N23: =-N22*($C$4) -> -1072.0459 | P23: Tax Expense | Q23: =-Q22*($C$4) -> -514.3656 | R23: =-R22*($C$4) -> -547.79936 | S23: =-S22*($C$4) -> -583.40632 | T23: =-T22*($C$4) -> -621.32773 | U23: =-U22*($C$4) -> -661.71404
B24: Interest Expense | C24: =$C$8*C18 -> -188.87735 | D24: =$C$8*D18 -> -203.04315 | E24: =$C$8*E18 -> -218.27138 | F24: =$C$8*F18 -> -234.64174 | G24: =$C$8*G18 -> -252.23987 | I24: Interest Expense | J24: =$J$8*J18 -> -190.63435 | K24: =$J$8*K18 -> -206.83826 | L24: =$J$8*L18 -> -224.41952 | M24: =$J$8*M18 -> -243.49518 | N24: =$J$8*N18 -> -264.19227 | P24: Interest Expense | Q24: =$Q$8*Q18 -> -187.12035 | R24: =$Q$8*R18 -> -199.28317 | S24: =$Q$8*S18 -> -212.23658 | T24: =$Q$8*T18 -> -226.03195 | U24: =$Q$8*U18 -> -240.72403
B25: Net Income | C25: =SUM(C22:C24) -> 1912.0844 | D25: =SUM(D22:D24) -> 2055.4907 | E25: =SUM(E22:E24) -> 2209.6525 | F25: =SUM(F22:F24) -> 2375.3764 | G25: =SUM(G22:G24) -> 2553.5297 | I25: Net Income | J25: =SUM(J22:J24) -> 2494.4919 | K25: =SUM(K22:K24) -> 2706.5237 | L25: =SUM(L22:L24) -> 2936.5783 | M25: =SUM(M22:M24) -> 3186.1874 | N25: =SUM(N22:N24) -> 3457.0133 | P25: Net Income | Q25: =SUM(Q22:Q24) -> 1598.307 | R25: =SUM(R22:R24) -> 1702.197 | S25: =SUM(S22:S24) -> 1812.8398 | T25: =SUM(T22:T24) -> 1930.6743 | U25: =SUM(U22:U24) -> 2056.1682
B26: Dep and Amort | C26: =$C$9*C18 -> 22.290036 | D26: =$C$9*D18 -> 23.961789 | E26: =$C$9*E18 -> 25.758923 | F26: =$C$9*F18 -> 27.690842 | G26: =$C$9*G18 -> 29.767656 | I26: Dep and Amort | J26: =$C$9*J18 -> 22.497385 | K26: =$C$9*K18 -> 24.409663 | L26: =$C$9*L18 -> 26.484485 | M26: =$C$9*M18 -> 28.735666 | N26: =$C$9*N18 -> 31.178197 | P26: Dep and Amort | Q26: =$Q$9*Q18 -> 22.082687 | R26: =$Q$9*R18 -> 23.518062 | S26: =$Q$9*S18 -> 25.046736 | T26: =$Q$9*T18 -> 26.674774 | U26: =$Q$9*U18 -> 28.408634
B27: Change in NWC | C27: -301.37 | D27: {=-'EBAY Balance Sheet'!$R$5:$U$5} -> -346.03867 | E27: -371.99157 | F27: -399.89094 | G27: -429.88276 | I27: Change in NWC | J27: -301.37 | K27: {=-'EBAY Balance Sheet'!$R$5:$U$5} -> -346.03867 | L27: -371.99157 | M27: -399.89094 | N27: -429.88276 | P27: Change in NWC | Q27: -301.37 | R27: {=-'EBAY Balance Sheet'!$R$5:$U$5} -> -346.03867 | S27: -371.99157 | T27: -399.89094 | U27: -429.88276
B28: Captial Expendatures | C28: {=-'EBAY Balance Sheet'!H20:L20} -> -270.86582 | D28: -115.03994 | E28: -123.66793 | F28: -132.94303 | G28: -142.91375 | I28: Captial Expendatures | J28: {=-'EBAY Balance Sheet'!H23:L23} -> -285.13434 | K28: -131.59142 | L28: -142.77669 | M28: -154.91271 | N28: -168.08029 | P28: Captial Expendatures | Q28: {=-'EBAY Balance Sheet'!H26:L26} -> -256.5973 | R28: -98.773825 | S28: -105.19412 | T28: -112.03174 | U28: -119.3138
B29: Long term debt issuance | C29: =$C$11*C18 -> 1018.7435 | D29: =$C$11*D18 -> 1095.1493 | E29: =$C$11*E18 -> 1177.2855 | F29: =$C$11*F18 -> 1265.5819 | G29: =$C$11*G18 -> 1360.5005 | I29: Long term debt issuance | J29: =$J$11*J18 -> 1227.276 | K29: =$J$11*K18 -> 1331.5945 | L29: =$J$11*L18 -> 1444.78 | M29: =$J$11*M18 -> 1567.5864 | N29: =$J$11*N18 -> 1700.8312 | P29: Long term debt issuance | Q29: =$Q$11*Q18 -> 1009.2668 | R29: =$Q$11*R18 -> 1074.8692 | S29: =$Q$11*S18 -> 1144.7357 | T29: =$Q$11*T18 -> 1219.1435 | U29: =$Q$11*U18 -> 1298.3878
B30: Long term debt repayments | C30: =$C$12*C18 -> -1554.4145 | D30: =$C$12*D18 -> -1670.9956 | E30: =$C$12*E18 -> -1796.3203 | F30: =$C$12*F18 -> -1931.0443 | G30: =$C$12*G18 -> -2075.8726 | I30: Long term debt repayments | J30: =$C$12*J18 -> -1568.8742 | K30: =$C$12*K18 -> -1702.2285 | L30: =$C$12*L18 -> -1846.9179 | M30: =$C$12*M18 -> -2003.9059 | N30: =$C$12*N18 -> -2174.2379 | P30: Long term debt repayments | Q30: =$Q$12*Q18 -> -1752.2232 | R30: =$Q$12*R18 -> -1866.1177 | S30: =$Q$12*S18 -> -1987.4154 | T30: =$Q$12*T18 -> -2116.5974 | U30: =$Q$12*U18 -> -2254.1762
B31: FCFE | C31: =SUM(C25:C30) -> 826.4676 | D31: =SUM(D25:D30) -> 1042.5276 | E31: =SUM(E25:E30) -> 1120.7171 | F31: =SUM(F25:F30) -> 1204.7709 | G31: =SUM(G25:G30) -> 1295.1287 | I31: FCFE | J31: =SUM(J25:J30) -> 1588.8869 | K31: =SUM(K25:K30) -> 1882.6693 | L31: =SUM(L25:L30) -> 2046.1566 | M31: =SUM(M25:M30) -> 2223.7999 | N31: =SUM(N25:N30) -> 2416.8218 | P31: FCFE | Q31: =SUM(Q25:Q30) -> 319.46603 | R31: =SUM(R25:R30) -> 489.654 | S31: =SUM(S25:S30) -> 518.02112 | T31: =SUM(T25:T30) -> 547.97258 | U31: =SUM(U25:U30) -> 579.59189
B32: Present Value | C32: =-PV($C$13,C16,0,C31) -> 763.76076 | D32: =-PV($C$13,D16,0,D31) -> 890.32909 | E32: =-PV($C$13,E16,0,E31) -> 884.48512 | F32: =-PV($C$13,F16,0,F31) -> 878.67952 | G32: =-PV($C$13,G16,0,G31) -> 872.91202 | I32: Present Value | J32: =-PV($C$13,J16,0,J31) -> 1468.3327 | K32: =-PV($C$13,K16,0,K31) -> 1607.8187 | L32: =-PV($C$13,L16,0,L31) -> 1614.8545 | M32: =-PV($C$13,M16,0,M31) -> 1621.8912 | N32: =-PV($C$13,N16,0,N31) -> 1628.929 | P32: Present Value | Q32: =-PV($C$13,Q16,0,Q31) -> 295.22708 | R32: =-PV($C$13,R16,0,R31) -> 418.16947 | S32: =-PV($C$13,S16,0,S31) -> 408.82928 | T32: =-PV($C$13,T16,0,T31) -> 399.65463 | U32: =-PV($C$13,U16,0,U31) -> 390.64281
B34: Sum of PV of FCFE | C34: =SUM(C32:G32) -> 4290.1665 | I34: Sum of PV of FCFE | J34: =SUM(J32:N32) -> 7941.8261 | P34: Sum of PV of FCFE | Q34: =SUM(Q32:U32) -> 1912.5233
B35: Terminal Value of FCFE | C35: =-PV(C13,6,0,G31/(C13-C14)) -> 14126.842 | I35: Terminal Value of FCFE | J35: =-PV(J13,6,0,N31/(J13-J14)) -> 27318.731 | P35: Terminal Value of FCFE | Q35: =-PV(Q13,6,0,U31/(Q13-Q14)) -> 6108.0668
B36: Equity Value | C36: =SUM(C34:C35) -> 18417.009 | I36: Equity Value | J36: =SUM(J34:J35) -> 35260.557 | P36: Equity Value | Q36: =SUM(Q34:Q35) -> 8020.59
B38: Shares Outstanding (M) | C38: 479 | I38: Shares Outstanding (M) | J38: 479 | P38: Shares Outstanding (M) | Q38: 479
B39: Equity Per Share | C39: =C36/C38 -> 38.44887 | I39: Equity Per Share | J39: =J36/J38 -> 73.612854 | P39: Equity Per Share | Q39: =Q36/Q38 -> 16.744447
B41: Current Market Value | C41: 67.05 | I41: Current Market Value | J41: 67.05 | P41: Current Market Value | Q41: 67.05
B42: Valuation Gap | C42: =(C39-C41)/C41 -> -0.42656421 | D42: SELL | I42: Valuation Gap | J42: =(J39-J41)/J41 -> 0.097880005 | K42: BUY | P42: Valuation Gap | Q42: =(Q39-Q41)/Q41 -> -0.75026925 | R42: SELL

Sheet CI - Stock PX
A1: Security | B1: CI US Equity | C1: KEY | D1: calculated row | E1: Non useful
A2: Start Date | B2: 43553
A3: End Date | B3: 45747
A4: Period | B4: M
A5: Currency | B5: USD
A7: Date | B7: Lookup Date | C7: PX_LAST | D7: Dividends paid | E7: PX_Change | F7: Risk Free (10yrbd) | G7: Return
A8: 45747 | B8: =_xlfn.CONCAT(MONTH(A8),"-",YEAR(A8)) -> 3-2025 | C8: 329.18 | D8: =IFERROR(INDEX('CI - dividend'!H:H,MATCH(B8,'CI - dividend'!D:D,0)),0) -> 1.51 | E8: =((C8+D8)-(C9+D9))/(C8+D8) -> 0.066588043 | F8: =INDEX('10YR Treasury'!E:E,MATCH(B8,'10YR Treasury'!B:B,0)) -> 0.0035044167 | G8: =E8-F8 -> 0.063083627
A9: 45716 | B9: =_xlfn.CONCAT(MONTH(A9),"-",YEAR(A9)) -> 2-2025 | C9: 308.67 | D9: =IFERROR(INDEX('CI - dividend'!H:H,MATCH(B9,'CI - dividend'!D:D,0)),0) -> 0 | E9: =((C9+D9)-(C10+D10))/(C9+D9) -> 0.046878543 | F9: =INDEX('10YR Treasury'!E:E,MATCH(B9,'10YR Treasury'!B:B,0)) -> 0.0035068333 | G9: =E9-F9 -> 0.04337171
A10: 45688 | B10: =_xlfn.CONCAT(MONTH(A10),"-",YEAR(A10)) -> 1-2025 | C10: 294.2 | D10: =IFERROR(INDEX('CI - dividend'!H:H,MATCH(B10,'CI - dividend'!D:D,0)),0) -> 0 | E10: =((C10+D10)-(C11+D11))/(C10+D10) -> 0.056152277 | F10: =INDEX('10YR Treasury'!E:E,MATCH(B10,'10YR Treasury'!B:B,0)) -> 0.00378225 | G10: =E10-F10 -> 0.052370027
A11: 45657 | B11: =_xlfn.CONCAT(MONTH(A11),"-",YEAR(A11)) -> 12-2024 | C11: 276.28 | D11: =IFERROR(INDEX('CI - dividend'!H:H,MATCH(B11,'CI - dividend'!D:D,0)),0) -> 1.4 | E11: =((C11+D11)-(C12+D12))/(C11+D11) -> -0.21654422 | F11: =INDEX('10YR Treasury'!E:E,MATCH(B11,'10YR Treasury'!B:B,0)) -> 0.0038075 | G11: =E11-F11 -> -0.22035172
A12: 45625 | B12: =_xlfn.CONCAT(MONTH(A12),"-",YEAR(A12)) -> 11-2024 | C12: 337.81 | D12: =IFERROR(INDEX('CI - dividend'!H:H,MATCH(B12,'CI - dividend'!D:D,0)),0) -> 0 | E12: =((C12+D12)-(C13+D13))/(C12+D12) -> 0.068766466 | F12: =INDEX('10YR Treasury'!E:E,MATCH(B12,'10YR Treasury'!B:B,0)) -> 0.00347375 | G12: =E12-F12 -> 0.065292716
A13: 45596 | B13: =_xlfn.CONCAT(MONTH(A13),"-",YEAR(A13)) -> 10-2024 | C13: 314.58 | D13: =IFERROR(INDEX('CI - dividend'!H:H,MATCH(B13,'CI - dividend'!D:D,0)),0) -> 0 | E13: =((C13+D13)-(C14+D14))/(C13+D13) -> -0.10569648 | F13: =INDEX('10YR Treasury'!E:E,MATCH(B13,'10YR Treasury'!B:B,0)) -> 0.0035703333 | G13: =E13-F13 -> -0.10926682
A14: 45565 | B14: =_xlfn.CONCAT(MONTH(A14),"-",YEAR(A14)) -> 9-2024 | C14: 346.43 | D14: =IFERROR(INDEX('CI - dividend'!H:H,MATCH(B14,'CI - dividend'!D:D,0)),0) -> 1.4 | E14: =((C14+D14)-(C15+D15))/(C14+D14) -> -0.039732053 | F14: =INDEX('10YR Treasury'!E:E,MATCH(B14,'10YR Treasury'!B:B,0)) -> 0.00315075 | G14: =E14-F14 -> -0.042882803
A15: 45534 | B15: =_xlfn.CONCAT(MONTH(A15),"-",YEAR(A15)) -> 8-2024 | C15: 361.65 | D15: =IFERROR(INDEX('CI - dividend'!H:H,MATCH(B15,'CI - dividend'!D:D,0)),0) -> 0 | E15: =((C15+D15)-(C16+D16))/(C15+D15) -> 0.0357528 | F15: =INDEX('10YR Treasury'!E:E,MATCH(B15,'10YR Treasury'!B:B,0)) -> 0.0032528333 | G15: =E15-F15 -> 0.032499966
A16: 45504 | B16: =_xlfn.CONCAT(MONTH(A16),"-",YEAR(A16)) -> 7-2024 | C16: 348.72 | D16: =IFERROR(INDEX('CI - dividend'!H:H,MATCH(B16,'CI - dividend'!D:D,0)),0) -> 0 | E16: =((C16+D16)-(C17+D17))/(C16+D16) -> 0.049151181 | F16: =INDEX('10YR Treasury'!E:E,MATCH(B16,'10YR Treasury'!B:B,0)) -> 0.003358 | G16: =E16-F16 -> 0.045793181
A17: 45471 | B17: =_xlfn.CONCAT(MONTH(A17),"-",YEAR(A17)) -> 6-2024 | C17: 330.18 | D17: =IFERROR(INDEX('CI - dividend'!H:H,MATCH(B17,'CI - dividend'!D:D,0)),0) -> 1.4 | E17: =((C17+D17)-(C18+D18))/(C17+D17) -> -0.038301466 | F17: =INDEX('10YR Treasury'!E:E,MATCH(B17,'10YR Treasury'!B:B,0)) -> 0.0036634167 | G17: =E17-F17 -> -0.041964882
A18: 45443 | B18: =_xlfn.CONCAT(MONTH(A18),"-",YEAR(A18)) -> 5-2024 | C18: 344.28 | D18: =IFERROR(INDEX('CI - dividend'!H:H,MATCH(B18,'CI - dividend'!D:D,0)),0) -> 0 | E18: =((C18+D18)-(C19+D19))/(C18+D18) -> -0.037469502 | F18: =INDEX('10YR Treasury'!E:E,MATCH(B18,'10YR Treasury'!B:B,0)) -> 0.00374875 | G18: =E18-F18 -> -0.041218252
A19: 45412 | B19: =_xlfn.CONCAT(MONTH(A19),"-",YEAR(A19)) -> 4-2024 | C19: 357.18 | D19: =IFERROR(INDEX('CI - dividend'!H:H,MATCH(B19,'CI - dividend'!D:D,0)),0) -> 0 | E19: =((C19+D19)-(C20+D20))/(C19+D19) -> -0.020745842 | F19: =INDEX('10YR Treasury'!E:E,MATCH(B19,'10YR Treasury'!B:B,0)) -> 0.0038998333 | G19: =E19-F19 -> -0.024645676
... A67: 43951 | B67: =_xlfn.CONCAT(MONTH(A67),"-",YEAR(A67)) -> 4-2020 | C67: 195.98 | D67: =IFERROR(INDEX('CI - dividend'!H:H,MATCH(B67,'CI - dividend'!D:D,0)),0) -> 0 | E67: =((C67+D67)-(C68+D68))/(C67+D67) -> 0.097663027 | F67: =INDEX('10YR Treasury'!E:E,MATCH(B67,'10YR Treasury'!B:B,0)) -> 0.00053275 | G67: =E67-F67 -> 0.097130277
A68: 43921 | B68: =_xlfn.CONCAT(MONTH(A68),"-",YEAR(A68)) -> 3-2020 | C68: 176.8 | D68: =IFERROR(INDEX('CI - dividend'!H:H,MATCH(B68,'CI - dividend'!D:D,0)),0) -> 0.04 | F68: =INDEX('10YR Treasury'!E:E,MATCH(B68,'10YR Treasury'!B:B,0)) -> 0.00055791667
B69: AVG | C69: =AVERAGE(C9:C68) -> 264.18267 | E69: =AVERAGE(E9:E68) -> 0.0061939937 | F69: =AVERAGE(F9:F68) -> 0.0023264222 | G69: =AVERAGE(G9:G68) -> 0.0038375968
B70: SD | C70: =STDEV(C9:C68) -> 55.504376 | E70: =STDEV(E9:E68) -> 0.080452342 | F70: =STDEV(F9:F68) -> 0.0011952435 | G70: =STDEV(G9:G68) -> 0.080513731
B71: total | C71: =(C8-C68)/C68 -> 0.86187783 | E71: geometric average

Sheet CI - dividend
B1: Declarati…↓ | C1: Ex Date | D1: Lookup Date | E1: Record | F1: Payable | G1: Curr | H1: Amount | I1: Type | J1: quarter end price
A2: 12) | B2: 45687 | C2: 45721 | D2: =_xlfn.CONCAT(MONTH(C2),"-",YEAR(C2)) -> 3-2025 | E2: 45721 | F2: 45736 | G2: USD | H2: 1.51 | I2: Regular Cash | J2: =INDEX('CI - Stock PX'!C:C,MATCH(D2,'CI - Stock PX'!B:B,0)) -> 329.18
A3: 13) | B3: 45588 | C3: 45630 | D3: =_xlfn.CONCAT(MONTH(C3),"-",YEAR(C3)) -> 12-2024 | E3: 45630 | F3: 45645 | G3: USD | H3: 1.4 | I3: Regular Cash | J3: =INDEX('CI - Stock PX'!C:C,MATCH(D3,'CI - Stock PX'!B:B,0)) -> 276.28
A4: 14) | B4: 45497 | C4: 45539 | D4: =_xlfn.CONCAT(MONTH(C4),"-",YEAR(C4)) -> 9-2024 | E4: 45539 | F4: 45554 | G4: USD | H4: 1.4 | I4: Regular Cash | J4: =INDEX('CI - Stock PX'!C:C,MATCH(D4,'CI - Stock PX'!B:B,0)) -> 346.43
A5: 15) | B5: 45406 | C5: 45447 | D5: =_xlfn.CONCAT(MONTH(C5),"-",YEAR(C5)) -> 6-2024 | E5: 45447 | F5: 45463 | G5: USD | H5: 1.4 | I5: Regular Cash | J5: =INDEX('CI - Stock PX'!C:C,MATCH(D5,'CI - Stock PX'!B:B,0)) -> 330.18
A6: 16) | B6: 45324 | C6: 45356 | D6: =_xlfn.CONCAT(MONTH(C6),"-",YEAR(C6)) -> 3-2024 | E6: 45357 | F6: 45372 | G6: USD | H6: 1.4 | I6: Regular Cash | J6: =INDEX('CI - Stock PX'!C:C,MATCH(D6,'CI - Stock PX'!B:B,0)) -> 363.19
A7: 17) | B7: 45224 | C7: 45265 | D7: =_xlfn.CONCAT(MONTH(C7),"-",YEAR(C7)) -> 12-2023 | E7: 45266 | F7: 45281 | G7: USD | H7: 1.23 | I7: Regular Cash | J7: =INDEX('CI - Stock PX'!C:C,MATCH(D7,'CI - Stock PX'!B:B,0)) -> 299.51
A8: 18) | B8: 45133 | C8: 45174 | D8: =_xlfn.CONCAT(MONTH(C8),"-",YEAR(C8)) -> 9-2023 | E8: 45175 | F8: 45190 | G8: USD | H8: 1.23 | I8: Regular Cash | J8: =INDEX('CI - Stock PX'!C:C,MATCH(D8,'CI - Stock PX'!B:B,0)) -> 286.08
A9: 19) | B9: 45042 | C9: 45083 | D9: =_xlfn.CONCAT(MONTH(C9),"-",YEAR(C9)) -> 6-2023 | E9: 45084 | F9: 45099 | G9: USD | H9: 1.23 | I9: Regular Cash | J9: =INDEX('CI - Stock PX'!C:C,MATCH(D9,'CI - Stock PX'!B:B,0)) -> 280.51
A10: 20) | B10: 44960 | C10: 44992 | D10: =_xlfn.CONCAT(MONTH(C10),"-",YEAR(C10)) -> 3-2023 | E10: 44993 | F10: 45008 | G10: USD | H10: 1.23 | I10: Regular Cash | J10: =INDEX('CI - Stock PX'!C:C,MATCH(D10,'CI - Stock PX'!B:B,0)) -> 255.31
A11: 21) | B11: 44860 | C11: 44900 | D11: =_xlfn.CONCAT(MONTH(C11),"-",YEAR(C11)) -> 12-2022 | E11: 44901 | F11: 44916 | G11: USD | H11: 1.12 | I11: Regular Cash | J11: =INDEX('CI - Stock PX'!C:C,MATCH(D11,'CI - Stock PX'!B:B,0)) -> 331.37
A12: 22) | B12: 44769 | C12: 44810 | D12: =_xlfn.CONCAT(MONTH(C12),"-",YEAR(C12)) -> 9-2022 | E12: 44811 | F12: 44826 | G12: USD | H12: 1.12 | I12: Regular Cash | J12: =INDEX('CI - Stock PX'!C:C,MATCH(D12,'CI - Stock PX'!B:B,0)) -> 277.7
A13: 23) | B13: 44678 | C13: 44719 | D13: =_xlfn.CONCAT(MONTH(C13),"-",YEAR(C13)) -> 6-2022 | E13: 44720 | F13: 44735 | G13: USD | H13: 1.12 | I13: Regular Cash | J13: =INDEX('CI - Stock PX'!C:C,MATCH(D13,'CI - Stock PX'!B:B,0)) -> 263.54
... A19: 29) | B19: 43887 | C19: 43899 | D19: =_xlfn.CONCAT(MONTH(C19),"-",YEAR(C19)) -> 3-2020 | E19: 43900 | F19: 43930 | G19: USD | H19: 0.04 | I19: Regular Cash | J19: =INDEX('CI - Stock PX'!C:C,MATCH(D19,'CI - Stock PX'!B:B,0)) -> 176.8
H20: =AVERAGE(H2:H19) -> 1.1416667

Sheet KMB - Stock PX
A1: Security | B1: KMB US Equity
A2: Start Date | B2: 43553
A3: End Date | B3: 45747
A4: Period | B4: M
A5: Currency | B5: USD
A7: Date | B7: Lookup Date | C7: PX_LAST | D7: Dividends | E7: PX_Change | F7: Risk Free (10yrbd) | G7: Return
A8: 45747 | B8: =_xlfn.CONCAT(MONTH(A8),"-",YEAR(A8)) -> 3-2025 | C8: 142.22 | D8: =IFERROR(INDEX('KMB - Dividends '!H:H,MATCH(B8,'KMB - Dividends '!D:D,0)),0) -> 1.26 | E8: =((C8+D8)-(C9+D9))/(C8+D8) -> 0.01024533 | F8: =INDEX('10YR Treasury'!E:E,MATCH(B8,'10YR Treasury'!B:B,0)) -> 0.0035044167 | G8: =E8-F8 -> 0.0067409137
A9: 45716 | B9: =_xlfn.CONCAT(MONTH(A9),"-",YEAR(A9)) -> 2-2025 | C9: 142.01 | D9: =IFERROR(INDEX('KMB - Dividends '!H:H,MATCH(B9,'KMB - Dividends '!D:D,0)),0) -> 0 | E9: =((C9+D9)-(C10+D10))/(C9+D9) -> 0.084782762 | F9: =INDEX('10YR Treasury'!E:E,MATCH(B9,'10YR Treasury'!B:B,0)) -> 0.0035068333 | G9: =E9-F9 -> 0.081275928
A10: 45688 | B10: =_xlfn.CONCAT(MONTH(A10),"-",YEAR(A10)) -> 1-2025 | C10: 129.97 | D10: =IFERROR(INDEX('KMB - Dividends '!H:H,MATCH(B10,'KMB - Dividends '!D:D,0)),0) -> 0 | E10: =((C10+D10)-(C11+D11))/(C10+D10) -> -0.017619451 | F10: =INDEX('10YR Treasury'!E:E,MATCH(B10,'10YR Treasury'!B:B,0)) -> 0.00378225 | G10: =E10-F10 -> -0.021401701
A11: 45657 | B11: =_xlfn.CONCAT(MONTH(A11),"-",YEAR(A11)) -> 12-2024 | C11: 131.04 | D11: =IFERROR(INDEX('KMB - Dividends '!H:H,MATCH(B11,'KMB - Dividends '!D:D,0)),0) -> 1.22 | E11: =((C11+D11)-(C12+D12))/(C11+D11) -> -0.053606533 | F11: =INDEX('10YR Treasury'!E:E,MATCH(B11,'10YR Treasury'!B:B,0)) -> 0.0038075 | G11: =E11-F11 -> -0.057414033
A12: 45625 | B12: =_xlfn.CONCAT(MONTH(A12),"-",YEAR(A12)) -> 11-2024 | C12: 139.35 | D12: =IFERROR(INDEX('KMB - Dividends '!H:H,MATCH(B12,'KMB - Dividends '!D:D,0)),0) -> 0 | E12: =((C12+D12)-(C13+D13))/(C12+D12) -> 0.037100825 | F12: =INDEX('10YR Treasury'!E:E,MATCH(B12,'10YR Treasury'!B:B,0)) -> 0.00347375 | G12: =E12-F12 -> 0.033627075
A13: 45596 | B13: =_xlfn.CONCAT(MONTH(A13),"-",YEAR(A13)) -> 10-2024 | C13: 134.18 | D13: =IFERROR(INDEX('KMB - Dividends '!H:H,MATCH(B13,'KMB - Dividends '!D:D,0)),0) -> 0 | E13: =((C13+D13)-(C14+D14))/(C13+D13) -> -0.069458936 | F13: =INDEX('10YR Treasury'!E:E,MATCH(B13,'10YR Treasury'!B:B,0)) -> 0.0035703333 | G13: =E13-F13 -> -0.073029269
A14: 45565 | B14: =_xlfn.CONCAT(MONTH(A14),"-",YEAR(A14)) -> 9-2024 | C14: 142.28 | D14: =IFERROR(INDEX('KMB - Dividends '!H:H,MATCH(B14,'KMB - Dividends '!D:D,0)),0) -> 1.22 | E14: =((C14+D14)-(C15+D15))/(C14+D14) -> -0.0080836237 | F14: =INDEX('10YR Treasury'!E:E,MATCH(B14,'10YR Treasury'!B:B,0)) -> 0.00315075 | G14: =E14-F14 -> -0.011234374
A15: 45534 | B15: =_xlfn.CONCAT(MONTH(A15),"-",YEAR(A15)) -> 8-2024 | C15: 144.66 | D15: =IFERROR(INDEX('KMB - Dividends '!H:H,MATCH(B15,'KMB - Dividends '!D:D,0)),0) -> 0 | E15: =((C15+D15)-(C16+D16))/(C15+D15) -> 0.066431633 | F15: =INDEX('10YR Treasury'!E:E,MATCH(B15,'10YR Treasury'!B:B,0)) -> 0.0032528333 | G15: =E15-F15 -> 0.063178799
A16: 45504 | B16: =_xlfn.CONCAT(MONTH(A16),"-",YEAR(A16)) -> 7-2024 | C16: 135.05 | D16: =IFERROR(INDEX('KMB - Dividends '!H:H,MATCH(B16,'KMB - Dividends '!D:D,0)),0) -> 0 | E16: =((C16+D16)-(C17+D17))/(C16+D16) -> -0.032358386 | F16: =INDEX('10YR Treasury'!E:E,MATCH(B16,'10YR Treasury'!B:B,0)) -> 0.003358 | G16: =E16-F16 -> -0.035716386
A17: 45471 | B17: =_xlfn.CONCAT(MONTH(A17),"-",YEAR(A17)) -> 6-2024 | C17: 138.2 | D17: =IFERROR(INDEX('KMB - Dividends '!H:H,MATCH(B17,'KMB - Dividends '!D:D,0)),0) -> 1.22 | E17: =((C17+D17)-(C18+D18))/(C17+D17) -> 0.043896141 | F17: =INDEX('10YR Treasury'!E:E,MATCH(B17,'10YR Treasury'!B:B,0)) -> 0.0036634167 | G17: =E17-F17 -> 0.040232724
A18: 45443 | B18: =_xlfn.CONCAT(MONTH(A18),"-",YEAR(A18)) -> 5-2024 | C18: 133.3 | D18: =IFERROR(INDEX('KMB - Dividends '!H:H,MATCH(B18,'KMB - Dividends '!D:D,0)),0) -> 0 | E18: =((C18+D18)-(C19+D19))/(C18+D18) -> -0.024231058 | F18: =INDEX('10YR Treasury'!E:E,MATCH(B18,'10YR Treasury'!B:B,0)) -> 0.00374875 | G18: =E18-F18 -> -0.027979808
A19: 45412 | B19: =_xlfn.CONCAT(MONTH(A19),"-",YEAR(A19)) -> 4-2024 | C19: 136.53 | D19: =IFERROR(INDEX('KMB - Dividends '!H:H,MATCH(B19,'KMB - Dividends '!D:D,0)),0) -> 0 | E19: =((C19+D19)-(C20+D20))/(C19+D19) -> 0.04365341 | F19: =INDEX('10YR Treasury'!E:E,MATCH(B19,'10YR Treasury'!B:B,0)) -> 0.0038998333 | G19: =E19-F19 -> 0.039753576
... A67: 43951 | B67: =_xlfn.CONCAT(MONTH(A67),"-",YEAR(A67)) -> 4-2020 | C67: 138.48 | D67: =IFERROR(INDEX('KMB - Dividends '!H:H,MATCH(B67,'KMB - Dividends '!D:D,0)),0) -> 0 | E67: =((C67+D67)-(C68+D68))/(C67+D67) -> 0.068890815 | F67: =INDEX('10YR Treasury'!E:E,MATCH(B67,'10YR Treasury'!B:B,0)) -> 0.00053275 | G67: =E67-F67 -> 0.068358065
A68: 43921 | B68: =_xlfn.CONCAT(MONTH(A68),"-",YEAR(A68)) -> 3-2020 | C68: 127.87 | D68: =IFERROR(INDEX('KMB - Dividends '!H:H,MATCH(B68,'KMB - Dividends '!D:D,0)),0) -> 1.07 | F68: =INDEX('10YR Treasury'!E:E,MATCH(B68,'10YR Treasury'!B:B,0)) -> 0.00055791667
B69: AVG | C69: =AVERAGE(C9:C68) -> 133.55183 | E69: =AVERAGE(E9:E68) -> 0.00015771709 | F69: =INDEX('10YR Treasury'!E:E,MATCH(B69,'10YR Treasury'!B:B,0)) -> 0.0023233374 | G69: =AVERAGE(G9:G68) -> -0.0021986798
B70: SD | C70: =STDEV(C9:C68) -> 8.0765466 | E70: =STDEV(E9:E68) -> 0.054719159 | F70: =INDEX('10YR Treasury'!E:E,MATCH(B70,'10YR Treasury'!B:B,0)) -> #N/A | G70: =STDEV(G9:G68) -> 0.054733304

Sheet KMB - Dividends 
B1: Declaration | C1: Ex Date | D1: Lookup Date | E1: record | F1: Payable | G1: Curr | H1: Amount | I1: Type | J1: quarter end price
A3: 12) | B3: 45685 | C3: 45723 | D3: =_xlfn.CONCAT(MONTH(C3),"-",YEAR(C3)) -> 3-2025 | E3: 45723 | F3: 45749 | G3: USD | H3: 1.26 | I3: Regular Cash | J3: =INDEX('KMB - Stock PX'!C:C,MATCH(D3,'KMB - Stock PX'!B:B,0)) -> 142.22
A4: 13) | B4: 45609 | C4: 45632 | D4: =_xlfn.CONCAT(MONTH(C4),"-",YEAR(C4)) -> 12-2024 | E4: 45632 | F4: 45660 | G4: USD | H4: 1.22 | I4: Regular Cash | J4: =INDEX('KMB - Stock PX'!C:C,MATCH(D4,'KMB - Stock PX'!B:B,0)) -> 131.04
A5: 14) | B5: 45505 | C5: 45541 | D5: =_xlfn.CONCAT(MONTH(C5),"-",YEAR(C5)) -> 9-2024 | E5: 45541 | F5: 45567 | G5: USD | H5: 1.22 | I5: Regular Cash | J5: =INDEX('KMB - Stock PX'!C:C,MATCH(D5,'KMB - Stock PX'!B:B,0)) -> 142.28
A6: 15) | B6: 45414 | C6: 45450 | D6: =_xlfn.CONCAT(MONTH(C6),"-",YEAR(C6)) -> 6-2024 | E6: 45450 | F6: 45475 | G6: USD | H6: 1.22 | I6: Regular Cash | J6: =INDEX('KMB - Stock PX'!C:C,MATCH(D6,'KMB - Stock PX'!B:B,0)) -> 138.2
A7: 16) | B7: 45315 | C7: 45358 | D7: =_xlfn.CONCAT(MONTH(C7),"-",YEAR(C7)) -> 3-2024 | E7: 45359 | F7: 45384 | G7: USD | H7: 1.22 | I7: Regular Cash | J7: =INDEX('KMB - Stock PX'!C:C,MATCH(D7,'KMB - Stock PX'!B:B,0)) -> 129.35
A8: 17) | B8: 45246 | C8: 45267 | D8: =_xlfn.CONCAT(MONTH(C8),"-",YEAR(C8)) -> 12-2023 | E8: 45268 | F8: 45294 | G8: USD | H8: 1.18 | I8: Regular Cash | J8: =INDEX('KMB - Stock PX'!C:C,MATCH(D8,'KMB - Stock PX'!B:B,0)) -> 121.51
A9: 18) | B9: 45139 | C9: 45176 | D9: =_xlfn.CONCAT(MONTH(C9),"-",YEAR(C9)) -> 9-2023 | E9: 45177 | F9: 45202 | G9: USD | H9: 1.18 | I9: Regular Cash | J9: =INDEX('KMB - Stock PX'!C:C,MATCH(D9,'KMB - Stock PX'!B:B,0)) -> 120.85
A10: 19) | B10: 45036 | C10: 45085 | D10: =_xlfn.CONCAT(MONTH(C10),"-",YEAR(C10)) -> 6-2023 | E10: 45086 | F10: 45112 | G10: USD | H10: 1.18 | I10: Regular Cash | J10: =INDEX('KMB - Stock PX'!C:C,MATCH(D10,'KMB - Stock PX'!B:B,0)) -> 138.06
A11: 20) | B11: 44951 | C11: 44994 | D11: =_xlfn.CONCAT(MONTH(C11),"-",YEAR(C11)) -> 3-2023 | E11: 44995 | F11: 45020 | G11: USD | H11: 1.18 | I11: Regular Cash | J11: =INDEX('KMB - Stock PX'!C:C,MATCH(D11,'KMB - Stock PX'!B:B,0)) -> 134.22
A12: 21) | B12: 44882 | C12: 44903 | D12: =_xlfn.CONCAT(MONTH(C12),"-",YEAR(C12)) -> 12-2022 | E12: 44904 | F12: 44930 | G12: USD | H12: 1.16 | I12: Regular Cash | J12: =INDEX('KMB - Stock PX'!C:C,MATCH(D12,'KMB - Stock PX'!B:B,0)) -> 135.75
A13: 22) | B13: 44774 | C13: 44812 | D13: =_xlfn.CONCAT(MONTH(C13),"-",YEAR(C13)) -> 9-2022 | E13: 44813 | F13: 44838 | G13: USD | H13: 1.16 | I13: Regular Cash | J13: =INDEX('KMB - Stock PX'!C:C,MATCH(D13,'KMB - Stock PX'!B:B,0)) -> 112.54
A14: 23) | B14: 44678 | C14: 44721 | D14: =_xlfn.CONCAT(MONTH(C14),"-",YEAR(C14)) -> 6-2022 | E14: 44722 | F14: 44747 | G14: USD | H14: 1.16 | I14: Regular Cash | J14: =INDEX('KMB - Stock PX'!C:C,MATCH(D14,'KMB - Stock PX'!B:B,0)) -> 135.15
... A23: 32) | B23: 43853 | C23: 43895 | D23: =_xlfn.CONCAT(MONTH(C23),"-",YEAR(C23)) -> 3-2020 | E23: 43896 | F23: 43923 | G23: USD | H23: 1.07 | I23: Regular Cash | J23: =INDEX('KMB - Stock PX'!C:C,MATCH(D23,'KMB - Stock PX'!B:B,0)) -> 127.87
H24: =AVERAGE(H3:H23) -> 1.1590476

Sheet EBAY - Stock PX
A1: Security | B1: EBAY US Equity
A2: Start Date | B2: 43553
A3: End Date | B3: 45747
A4: Period | B4: M
A5: Currency | B5: USD
A7: Date | B7: Lookup Date | C7: PX_LAST | D7: Dividends | E7: PX_Change | F7: Risk Free (10yrbd) | G7: Return
A8: 45747 | B8: =_xlfn.CONCAT(MONTH(A8),"-",YEAR(A8)) -> 3-2025 | C8: 67.73 | D8: =IFERROR(INDEX('EBAY - Dividends'!H:H,MATCH(B8,'EBAY - Dividends'!D:D,0)),0) -> 0.29 | E8: =((C8+D8)-(C9+D9))/(C8+D8) -> 0.048221111 | F8: =INDEX('10YR Treasury'!E:E,MATCH(B8,'10YR Treasury'!B:B,0)) -> 0.0035044167 | G8: =E8-F8 -> 0.044716695
